2020-06-06 18:51:45 - Criar Nova Chave - {'status': 'Erro ao recuperar localização', 'details': 'Traceback (most recent call last):\n  File "c:\\program files (x86)\\python\\lib\\urllib\\request.py", line 1350, in do_open\n    h.request(req.get_method(), req.selector, req.data, headers,\n  File "c:\\program files (x86)\\python\\lib\\http\\client.py", line 1240, in request\n    self._send_request(method, url, body, headers, encode_chunked)\n  File "c:\\program files (x86)\\python\\lib\\http\\client.py", line 1286, in _send_request\n    self.endheaders(body, encode_chunked=encode_chunked)\n  File "c:\\program files (x86)\\python\\lib\\http\\client.py", line 1235, in endheaders\n    self._send_output(message_body, encode_chunked=encode_chunked)\n  File "c:\\program files (x86)\\python\\lib\\http\\client.py", line 1006, in _send_output\n    self.send(msg)\n  File "c:\\program files (x86)\\python\\lib\\http\\client.py", line 946, in send\n    self.connect()\n  File "c:\\program files (x86)\\python\\lib\\http\\client.py", line 1402, in connect\n    super().connect()\n  File "c:\\program files (x86)\\python\\lib\\http\\client.py", line 917, in connect\n    self.sock = self._create_connection(\n  File "c:\\program files (x86)\\python\\lib\\socket.py", line 787, in create_connection\n    for res in getaddrinfo(host, port, 0, SOCK_STREAM):\n  File "c:\\program files (x86)\\python\\lib\\socket.py", line 918, in getaddrinfo\n    for res in _socket.getaddrinfo(host, port, family, type, proto, flags):\nsocket.gaierror: [Errno 11001] getaddrinfo failed\n\nDuring handling of the above exception, another exception occurred:\n\nTraceback (most recent call last):\n  File "C:\\vsworkspaces\\Robotframework\\PrimeControlTest\\resources\\generateClanMembersCsv.py", line 23, in makeApiCall\n    return json.loads(urllib.request.urlopen(request).read().decode("utf-8"))\n  File "c:\\program files (x86)\\python\\lib\\urllib\\request.py", line 222, in urlopen\n    return opener.open(url, data, timeout)\n  File "c:\\program files (x86)\\python\\lib\\urllib\\request.py", line 525, in open\n    response = self._open(req, data)\n  File "c:\\program files (x86)\\python\\lib\\urllib\\request.py", line 542, in _open\n    result = self._call_chain(self.handle_open, protocol, protocol +\n  File "c:\\program files (x86)\\python\\lib\\urllib\\request.py", line 502, in _call_chain\n    result = func(*args)\n  File "c:\\program files (x86)\\python\\lib\\urllib\\request.py", line 1393, in https_open\n    return self.do_open(http.client.HTTPSConnection, req,\n  File "c:\\program files (x86)\\python\\lib\\urllib\\request.py", line 1353, in do_open\n    raise URLError(err)\nurllib.error.URLError: <urlopen error [Errno 11001] getaddrinfo failed>\n'} 
